Workbook

Sheet data
A1: Дата смены | B1: Город | C1: Название станции доставки | D1: Название компании курьера | E1: Ид смены курьера | F1: Плановое начало смены (время начала погрузки на станции доставки) | G1: Тип_авто | H1: Протяженность маршрута курьера, км (факт) | I1: Общее кол-во адресов доставки | J1: Кол-во адресов самовывоза | K1: Кол-во отсканированных на СЦ заказов | L1: Общее кол-во доставленных заказов | M1: Кол-во заказов в самовывоз | N1: Среднее время на станции доставки, мин (факт) | O1: Среднее время до 1-й точки маршрута, мин (факт) | P1: Среднее время на точке маршрута, мин (факт) | Q1: Среднее время между точками маршрута, мин (факт)
A2: 44197 | B2: =VLOOKUP(C2,[1]Город!C:E,3,0) -> Санкт-Петербург | C2: СД_2 | D2: Компания_1 | E2: 2591025 | F2: 08:30:00 | G2: Грузовая | H2: 153.3136 | I2: 30 | J2: 13 | K2: 138 | L2: 137 | M2: 117 | N2: 100.9 | O2: 86.866667 | P2: 4.7369792 | Q2: 4.9005376
A3: 44197 | B3: =VLOOKUP(C3,[1]Город!C:E,3,0) -> Самара | C3: СД_29 | D3: Компания_1 | E3: 2591910 | F3: 10:00:00 | G3: Легковая | H3: 221.84097 | I3: 19 | J3: 7 | K3: 143 | L3: 141 | M3: 119 | N3: 118.75 | O3: 42.75 | P3: 8.7991228 | Q3: 17.39537
A4: 44197 | B4: =VLOOKUP(C4,[1]Город!C:E,3,0) -> Екатеринбург | C4: СД_31 | D4: Компания_2 | E4: 2590736 | F4: 07:30:00 | G4: Легковая | H4: 84.452701 | I4: 19 | J4: 4 | K4: 115 | L4: 114 | M4: 72 | N4: 77.033333 | O4: 485.33333 | P4: 2.0992754 | Q4: 9.5704545
A5: 44197 | B5: =VLOOKUP(C5,[1]Город!C:E,3,0) -> Уфа | C5: СД_11 | D5: Компания_2 | E5: 2590864 | F5: 10:00:00 | G5: Грузовая | H5: 100.96031 | I5: 20 | J5: 7 | K5: 142 | L5: 141 | M5: 124 | N5: 156.43333 | O5: 109 | P5: 3.965 | Q5: 13.260526
A6: 44197 | B6: =VLOOKUP(C6,[1]Город!C:E,3,0) -> Самара | C6: СД_29 | D6: Компания_1 | E6: 2591867 | F6: 10:00:00 | G6: Грузовая | H6: 73.391196 | I6: 25 | J6: 6 | K6: 165 | L6: 165 | M6: 141 | N6: 143.66667 | O6: 34.466667 | P6: 3.0466667 | Q6: 12.029861
A7: 44197 | B7: =VLOOKUP(C7,[1]Город!C:E,3,0) -> Нижний Новгород | C7: СД_18 | D7: Компания_1 | E7: 2591294 | F7: 10:00:00 | G7: Легковая | H7: 290.63739 | I7: 28 | J7: 13 | K7: 81 | L7: 78 | M7: 61 | N7: 108.25 | O7: 91.016667 | P7: 7.2061111 | Q7: 9.8913793
A8: 44197 | B8: =VLOOKUP(C8,[1]Город!C:E,3,0) -> Москва | C8: СД_36 | D8: Компания_3 | E8: 2592218 | F8: 08:30:00 | G8: Грузовая | H8: 88.475914 | I8: 19 | J8: 4 | K8: 206 | L8: 203 | M8: 156 | N8: 160.93333 | O8: 66.983333 | P8: 9.2217391 | Q8: 15.457576
A9: 44197 | B9: =VLOOKUP(C9,[1]Город!C:E,3,0) -> Омск | C9: СД_9 | D9: Компания_4 | E9: 2592395 | F9: 09:00:00 | G9: Легковая | H9: 64.34807 | I9: 15 | J9: 5 | K9: 61 | L9: 60 | M9: 47 | N9: 54.983333 | O9: 28.733333 | P9: 4.4122222 | Q9: 3.0428571
A10: 44197 | B10: =VLOOKUP(C10,[1]Город!C:E,3,0) -> Казань | C10: СД_4 | D10: Компания_5 | E10: 2591122 | F10: 07:00:00 | G10: Грузовая | H10: 143.21552 | I10: 29 | J10: 7 | K10: 123 | L10: 122 | M10: 94 | N10: 111.81667 | O10: 79.833333 | P10: 2.1791667 | Q10: 7.308642
A11: 44197 | B11: =VLOOKUP(C11,[1]Город!C:E,3,0) -> Санкт-Петербург | C11: СД_2 | D11: Компания_3 | E11: 2591406 | F11: 10:00:00 | G11: Грузовая | H11: 105.41146 | I11: 41 | J11: 3 | K11: 133 | L11: 125 | M11: 75 | N11: 119.03333 | O11: 55.716667 | P11: 3.1130719 | Q11: 7.752
A12: 44197 | B12: =VLOOKUP(C12,[1]Город!C:E,3,0) -> Челябинск | C12: СД_12 | D12: Компания_5 | E12: 2590357 | F12: 11:00:00 | G12: Грузовая | H12: 80.499176 | I12: 18 | J12: 0 | K12: 18 | L12: 16 | M12: 0 | N12: 72.033333 | O12: 46.083333 | P12: 6.7211111 | Q12: 19.994048
A13: 44197 | B13: =VLOOKUP(C13,[1]Город!C:E,3,0) -> Московская область | C13: СД_37 | D13: Компания_1 | E13: 2591540 | F13: 11:00:00 | G13: Грузовая | H13: 152.53529 | I13: 19 | J13: 0 | K13: 21 | L13: 21 | M13: 0 | N13: 84.7 | O13: 7.6833333 | P13: 11.794444 | Q13: 8.3254902
... A26: 44197 | B26: =VLOOKUP(C26,[1]Город!C:E,3,0) -> Барнаул | C26: СД_14 | D26: Компания_2 | E26: 2592837 | F26: 09:00:00 | G26: Грузовая | H26: 73.088669 | I26: 22 | J26: 0 | K26: 25 | L26: 25 | M26: 0 | N26: 76.716667 | O26: 2.9666667 | P26: 5.2189394 | Q26: 14.726984
A27: 44197 | B27: =VLOOKUP(C27,[1]Город!C:E,3,0) -> Новосибирск | C27: СД_32 | D27: Компания_6 | E27: 2593767 | F27: 14:00:00 | G27: Грузовая | H27: 153.13849 | I27: 9 | J27: 3 | K27: 9 | L27: 9 | M27: 3 | N27: 55.9 | P27: 13.441667 | Q27: 23.364583
A28: 44197 | B28: =VLOOKUP(C28,[1]Город!C:E,3,0) -> Москва | C28: СД_33 | D28: Компания_6 | E28: 2590485 | F28: 10:00:00 | G28: Легковая | H28: 28.247853 | I28: 16 | J28: 1 | K28: 93 | L28: 93 | M28: 65 | N28: 74.233333 | O28: 28.4 | P28: 17.235417 | Q28: 7.8744444
A29: 44197 | B29: =VLOOKUP(C29,[1]Город!C:E,3,0) -> Красноярск | C29: СД_15 | D29: Компания_2 | E29: 2592697 | F29: 10:00:00 | G29: Грузовая | H29: 69.997422 | I29: 22 | J29: 6 | K29: 183 | L29: 176 | M29: 159 | N29: 187.58333 | O29: 31.983333 | P29: 4.6603175 | Q29: 18.563333
A30: 44197 | B30: =VLOOKUP(C30,[1]Город!C:E,3,0) -> Москва | C30: СД_33 | D30: Компания_6 | E30: 2590524 | F30: 10:00:00 | G30: Легковая | H30: 189.63325 | I30: 25 | J30: 7 | K30: 84 | L30: 82 | M30: 55 | N30: 73.116667 | O30: 28.95 | P30: 5.8273333 | Q30: 13.700694
A31: 44197 | B31: =VLOOKUP(C31,[1]Город!C:E,3,0) -> Волгоград | C31: СД_1 | D31: Компания_8 | E31: 2591675 | F31: 09:00:00 | G31: Грузовая | H31: 225.55031 | I31: 23 | J31: 0 | K31: 25 | L31: 25 | M31: 0 | N31: 111.4 | O31: 129.93333 | P31: 11.045652 | Q31: 8.0886364
A32: 44197 | B32: =VLOOKUP(C32,[1]Город!C:E,3,0) -> Москва | C32: СД_33 | D32: Компания_4 | E32: 2592688 | F32: 12:00:00 | G32: Грузовая | H32: 176.80887 | I32: 26 | J32: 9 | K32: 135 | L32: 133 | M32: 112 | N32: 112.7 | O32: 78.683333 | P32: 4.0192308 | Q32: 7.3467949
A33: 44197 | B33: =VLOOKUP(C33,[1]Город!C:E,3,0) -> Новосибирск | C33: СД_32 | D33: Компания_6 | E33: 2592150 | F33: 09:30:00 | G33: Грузовая | H33: 64.80304 | I33: 19 | J33: 6 | K33: 178 | L33: 177 | M33: 158 | N33: 131.33333 | O33: 33.35 | P33: 8.2605263 | Q33: 5.4333333
A34: 44197 | B34: =VLOOKUP(C34,[1]Город!C:E,3,0) -> Нижний Новгород | C34: СД_18 | D34: Компания_1 | E34: 2591201 | F34: 10:00:00 | G34: Легковая | H34: 412.99672 | I34: 27 | J34: 0 | K34: 37 | L34: 37 | M34: 0 | N34: 52.416667 | O34: 109.68333 | P34: 3.2871795 | Q34: 12.457692
A35: 44197 | B35: =VLOOKUP(C35,[1]Город!C:E,3,0) -> Омск | C35: СД_9 | D35: Компания_1 | E35: 2592365 | F35: 09:00:00 | G35: Грузовая | H35: 111.20517 | I35: 25 | J35: 8 | K35: 142 | L35: 141 | M35: 114 | N35: 104.2 | O35: 48.15 | P35: 5.3205128 | Q35: 8.7946667
A36: 44197 | B36: =VLOOKUP(C36,[1]Город!C:E,3,0) -> Волгоград | C36: СД_1 | D36: Компания_5 | E36: 2588458 | F36: 07:00:00 | G36: Грузовая | H36: 142.79156 | I36: 27 | J36: 0 | K36: 28 | L36: 27 | M36: 0 | N36: 165.5 | O36: 64.366667 | P36: 5.1482143 | Q36: 17.880247
A37: 44197 | B37: =VLOOKUP(C37,[1]Город!C:E,3,0) -> Екатеринбург | C37: СД_31 | D37: Компания_3 | E37: 2590758 | F37: 07:30:00 | G37: Грузовая | H37: 246.99728 | I37: 34 | J37: 7 | K37: 96 | L37: 95 | M37: 57 | N37: 126.36667 | O37: 127.35 | P37: 5.0424242 | Q37: 7.7744792
A38: 44197 | B38: =VLOOKUP(C38,[1]Город!C:E,3,0) -> Новосибирск | C38: СД_32 | D38: Компания_6 | E38: 2592151 | F38: 10:30:00 | G38: Грузовая | H38: 50.764822 | I38: 22 | J38: 8 | K38: 158 | L38: 155 | M38: 128 | N38: 120.68333 | O38: 5.8 | P38: 10.634058 | Q38: 9.5143939
A39: 44197 | B39: =VLOOKUP(C39,[1]Город!C:E,3,0) -> Москва | C39: СД_33 | D39: Компания_6 | E39: 2592626 | F39: 11:00:00 | G39: Легковая | H39: 111.5565 | I39: 21 | J39: 9 | K39: 115 | L39: 115 | M39: 102 | N39: 41.6 | O39: 34.566667 | P39: 3.8793651 | Q39: 10.871667
... A49: 44197 | B49: =VLOOKUP(C49,[1]Город!C:E,3,0) -> Красноярск | C49: СД_15 | D49: Компания_6 | E49: 2592702 | F49: 09:00:00 | G49: Грузовая | H49: 342.72132 | I49: 15 | J49: 0 | K49: 19 | L49: 18 | M49: 0 | N49: 63.866667 | O49: 30.016667 | P49: 4.5311111 | Q49: 29.927381
A50: 44197 | B50: =VLOOKUP(C50,[1]Город!C:E,3,0) -> Новосибирск | C50: СД_32 | D50: Компания_3 | E50: 2590429 | F50: 06:00:00 | G50: Грузовая | H50: 30.377606 | I50: 4 | J50: 4 | K50: 227 | L50: 226 | M50: 226 | N50: 286.1 | P50: 14.670833 | Q50: 18.166667
A51: 44197 | B51: =VLOOKUP(C51,[1]Город!C:E,3,0) -> Самара | C51: СД_29 | D51: Компания_5 | E51: 2593388 | F51: 10:00:00 | G51: Легковая | H51: 294.31454 | I51: 17 | J51: 0 | K51: 48 | L51: 33 | M51: 0 | N51: 98.466667 | O51: 152.63333 | P51: 4.5385965 | Q51: 12.171296
A52: 44197 | B52: =VLOOKUP(C52,[1]Город!C:E,3,0) -> Москва | C52: СД_33 | D52: Компания_2 | E52: 2592491 | F52: 11:00:00 | G52: Грузовая | H52: 134.34385 | I52: 32 | J52: 6 | K52: 171 | L52: 170 | M52: 130 | N52: 121.96667 | O52: 31.4 | P52: 4.6707071 | Q52: 9.3796875
A53: 44197 | B53: =VLOOKUP(C53,[1]Город!C:E,3,0) -> Москва | C53: СД_33 | D53: Компания_3 | E53: 2593136 | F53: 10:00:00 | G53: Легковая | H53: 375.31012 | I53: 19 | J53: 2 | K53: 48 | L53: 48 | M53: 13 | N53: 68.083333 | O53: 151.06667 | P53: 5.7421053 | Q53: 5.7898148
A54: 44197 | B54: =VLOOKUP(C54,[1]Город!C:E,3,0) -> Казань | C54: СД_4 | D54: Компания_2 | E54: 2591333 | F54: 09:30:00 | G54: Грузовая | H54: 103.18295 | I54: 26 | J54: 3 | K54: 64 | L54: 61 | M54: 28 | N54: 108.58333 | O54: 13.3 | P54: 9.6858974 | Q54: 5.1074074
A55: 44197 | B55: =VLOOKUP(C55,[1]Город!C:E,3,0) -> Новосибирск | C55: СД_32 | D55: Компания_5 | E55: 2590452 | F55: 06:00:00 | G55: Грузовая | H55: 78.105959 | I55: 5 | J55: 5 | K55: 225 | L55: 225 | M55: 225 | N55: 104.76667 | O55: 24.8 | P55: 14.963333 | Q55: 11.045833
A56: 44197 | B56: =VLOOKUP(C56,[1]Город!C:E,3,0) -> Красноярск | C56: СД_15 | D56: Компания_5 | E56: 2592700 | F56: 09:00:00 | G56: Легковая | H56: 289.32223 | I56: 25 | J56: 1 | K56: 57 | L56: 55 | M56: 8 | N56: 48.716667 | O56: 101.15 | P56: 7.1840278 | Q56: 3.0253623
A57: 44197 | B57: =VLOOKUP(C57,[1]Город!C:E,3,0) -> Челябинск | C57: СД_12 | D57: Компания_6 | E57: 2590327 | F57: 09:30:00 | G57: Грузовая | H57: 85.9681 | I57: 20 | J57: 5 | K57: 225 | L57: 213 | M57: 192 | N57: 234.55 | O57: 90.216667 | P57: 11.87 | Q57: 17.785088
A58: 44197 | B58: =VLOOKUP(C58,[1]Город!C:E,3,0) -> Екатеринбург | C58: СД_31 | D58: Компания_3 | E58: 2591559 | F58: 09:00:00 | G58: Грузовая | H58: 89.58634 | I58: 32 | J58: 1 | K58: 112 | L58: 109 | M58: 66 | N58: 139.03333 | O58: 89.816667 | P58: 4.2146825 | Q58: 7.6939024
A59: 44197 | B59: =VLOOKUP(C59,[1]Город!C:E,3,0) -> Санкт-Петербург | C59: СД_2 | D59: Компания_2 | E59: 2591192 | F59: 09:00:00 | G59: Грузовая | H59: 100.84628 | I59: 28 | J59: 13 | K59: 236 | L59: 231 | M59: 211 | N59: 122.35 | O59: 93.733333 | P59: 4.7632184 | Q59: 7.2660714
A60: 44197 | B60: =VLOOKUP(C60,[1]Город!C:E,3,0) -> Санкт-Петербург | C60: СД_2 | D60: Компания_2 | E60: 2591138 | F60: 09:00:00 | G60: Грузовая | H60: 209.24749 | I60: 40 | J60: 7 | K60: 87 | L60: 85 | M60: 45 | N60: 150.81667 | O60: 89.266667 | P60: 3.9641667 | Q60: 5.7858974
A61: 44197 | B61: =VLOOKUP(C61,[1]Город!C:E,3,0) -> Москва | C61: СД_33 | D61: Компания_1 | E61: 2592601 | F61: 10:00:00 | G61: Грузовая | H61: 103.28738 | I61: 19 | J61: 6 | K61: 194 | L61: 193 | M61: 180 | N61: 111.41667 | O61: 48.083333 | P61: 9.2964912 | Q61: 10.376852
...
